<?xml version="1.0"?>
<robot name="arm_3">

  <link name="base_link">

    <visual>
      <geometry>
	      <cylinder length="0.06" radius="0.1"/>
      </geometry>
      <origin rpy="0 0 0" xyz="0 0 0"/>
      <material name="red">
        <color rgba="1 0 0 1"/>
      </material>
    </visual>

    <collision>
      <geometry>
	      <cylinder length="0.05" radius="0.1"/>
      </geometry>
        <origin rpy="0 0 0" xyz="0 0 0"/>
    </collision>
    <inertial>
	<mass value="1"/>
	<inertia ixx="1.0" ixy="0.0" ixz="0.0" iyy="1.0" iyz="0.0" izz="1.0"/>
    </inertial>
  </link>

  <joint name="eslabon1" type="revolute">
    <parent link="base_link"/>
    <child link="eslabon1_link"/>
    <origin xyz="0 0 0.06"/>
    <axis xyz="0 0 1" />
    <limit effort="300" velocity="0.1" lower="-3.14" upper="3.14"/>
    <dynamics damping="50" friction="1"/>
  </joint>

  <link name="eslabon1_link">
    <visual>
      <geometry>
	      <cylinder length="0.3" radius="0.042"/>
      </geometry>
      <origin rpy="0 0 0" xyz="0 0 0.09"/>
      <material name="green">
        <color rgba="0 1 0 1"/>
      </material>
    </visual>
    <collision>
      <geometry>
	      <cylinder length="0.4" radius="0.06"/>
      </geometry>
      <origin rpy="0 0 0" xyz="0 0 0.08"/>
    </collision>
    <inertial>
	<mass value="1"/>
	<inertia ixx="1.0" ixy="0.0" ixz="0.0" iyy="1.0" iyz="0.0" izz="1.0"/>
    </inertial>
  </link>

  <joint name="eslabon2" type="revolute">
    <parent link="eslabon1_link"/>
    <child link="eslabon2_link"/>
      <origin rpy="0 0 0" xyz="0 0 0.25"/>
    <axis xyz="0 1 0" />
    <limit effort="300" velocity="0.1" lower="-2.5" upper="2.5"/>
    <dynamics damping="50" friction="1"/>
  </joint>

  <link name="eslabon2_link">
    <visual>
      <geometry>
	      <cylinder length="0.3" radius="0.04"/>
      </geometry>
      <origin rpy="0 0 0" xyz="0 0 0.1"/>
      <material name="red">
        <color rgba="1 0 0 1"/>
      </material>
    </visual>
    <collision>
      <geometry>
	      <cylinder length="0.3" radius="0.04"/>
      </geometry>
      <origin rpy="0 1.5 0" xyz="0 0 0"/>
    </collision>
    <inertial>
	<mass value="1"/>
	<inertia ixx="1.0" ixy="0.0" ixz="0.0" iyy="1.0" iyz="0.0" izz="1.0"/>
    </inertial>
  </link>

    <joint name="eslabon3" type="prismatic">
    <parent link="eslabon2_link"/>
    <child link="eslabon3_link"/>
    <origin rpy="0 0 0.05" xyz="0 0 0.05"/>
    <axis xyz="0 0 1" />
    <limit effort="300" velocity="0.1" lower="0" upper="0.19"/>
    <dynamics damping="50" friction="1"/>
  </joint>

  <link name="eslabon3_link">
    <visual>
      <geometry>
	<cylinder length="0.3" radius="0.02"/>
      </geometry>
      <origin rpy="0 0 0" xyz="0 0 0.08"/>
      <material name="blue">
        <color rgba="0 0 1 1"/>
      </material>
    </visual>
    <collision>
      <geometry>
	<cylinder length="0.4" radius="0.06"/>
      </geometry>
      <origin rpy="0 1.5 0" xyz="0 0 0"/>
    </collision>
    <inertial>
	<mass value="1"/>
	<inertia ixx="1.0" ixy="0.0" ixz="0.0" iyy="1.0" iyz="0.0" izz="1.0"/>
    </inertial>
  </link>

</robot>